<?xml version="1.0"?>
<robot xmlns:xacro="http://www.ros.org/wiki/xacro">
  <!-- Begin - Include -->
    <xacro:include filename="$(find rover_arm_resources_pkg)/urdf/common_materials.xacro"/>
  <!-- End - Include -->

  <!-- Joint Macro -->
  <!-- fixed joint -->
  <xacro:macro name="m_joint_fixed" params="name origin_xyz origin_rpy parent child">
    <!-- fixed joint -->
    <joint name="${name}" type="fixed">
      <origin rpy="${origin_rpy}" xyz="${origin_xyz}"/>
      <parent link="${parent}"/>
      <child link="${child}"/>
    </joint>
  </xacro:macro>

  <!-- continuous joint -->
  <xacro:macro name="m_joint_cont" params="name axis_xyz origin_xyz origin_rpy
               parent child limit_e limit_v damp fric">
    <joint name="${name}" type="continuous">
      <axis xyz="${axis_xyz}"/>
      <limit effort="${limit_e}" velocity="${limit_v}"/>
      <origin rpy="${origin_rpy}" xyz="${origin_xyz}"/>
      <parent link="${parent}"/>
      <child link="${child}"/>
      <dynamics damping="${damp}" friction="${fric}"/>
    </joint>
    <transmission name="trans_${name}">
      <type>transmission_interface/SimpleTransmission</type>
      <joint name="${name}">
        <hardwareInterface>hardware_interface/EffortJointInterface</hardwareInterface>
      </joint>
      <actuator name="motor_${name}">
        <!-- <hardwareInterface>hardware_interface/EffortJointInterface</hardwareInterface> -->
        <mechanicalReduction>1</mechanicalReduction>
      </actuator>
    </transmission>
  </xacro:macro>

  <!-- revolute joint -->
  <xacro:macro name="m_joint_rev" params="name axis_xyz axis_rpy origin_xyz
               origin_rpy parent child limit_e limit_l limit_u limit_v damp
               fric">
    <joint name="${name}" type="revolute">
      <axis rpy="axis_rpy" xyz="${axis_xyz}"/>
      <limit effort="${limit_e}" lower="${limit_l}" upper="${limit_u}" velocity="${limit_v}"/>
      <origin rpy="${origin_rpy}" xyz="${origin_xyz}"/>
      <parent link="${parent}"/>
      <child link="${child}"/>
      <dynamics damping="${damp}" friction="${fric}"/>
    </joint>
    <transmission name="trans_${name}">
      <type>transmission_interface/SimpleTransmission</type>
      <joint name="${name}">
        <hardwareInterface>hardware_interface/EffortJointInterface</hardwareInterface>
      </joint>
      <actuator name="motor_${name}">
        <!-- <hardwareInterface>hardware_interface/EffortJointInterface</hardwareInterface> -->
        <mechanicalReduction>1</mechanicalReduction>
      </actuator>
    </transmission>
  </xacro:macro>

  <!-- Cylinder link Macro without inertia -->
  <xacro:macro name="m_link_cylinder" params="name origin_xyz origin_rpy r l">
    <link name="${name}">
      <visual>
        <origin rpy="${origin_rpy}" xyz="${origin_xyz}"/>
        <geometry>
          <cylinder radius="${r}" length="${l}"/>
        </geometry>
        <xacro:material_gray/>
      </visual>
    </link>
  </xacro:macro>

  <!-- Cylinder link Macro with inertia -->
  <xacro:macro name="m_link_cylinder_inertia" params="name origin_xyz origin_rpy r l m">
    <link name="${name}">
      <inertial>
        <mass value="${m}"/>
        <origin rpy="${origin_rpy}" xyz="${origin_xyz}"/>
        <inertia ixx="${m*(3*r*r+l*l)/12}" ixy="0.0" ixz="0.0"
                 iyy="${m*(3*r*r+l*l)/12}" iyz="0.0"
                 izz="${m*r*r/2}"/>
      </inertial>
      <collision>
        <origin rpy="${origin_rpy}" xyz="${origin_xyz}"/>
        <geometry>
          <cylinder radius="${r}" length="${l}"/>
        </geometry>
      </collision>
      <visual>
        <origin rpy="${origin_rpy}" xyz="${origin_xyz}"/>
        <geometry>
          <cylinder radius="${r}" length="${l}"/>
        </geometry>
        <xacro:material_darkgray/>
      </visual>
    </link>
  </xacro:macro>

  <!-- Box link Macro without inertia -->
  <xacro:macro name="m_link_box" params="name origin_xyz origin_rpy w d h">
    <link name="${name}">
      <visual>
        <origin rpy="${origin_rpy}" xyz="${origin_xyz}"/>
        <geometry>
          <box size="${w} ${d} ${h}"/>
        </geometry>
        <xacro:material_white/>
      </visual>
    </link>
  </xacro:macro>

  <!-- Box link Macro with inertia -->
  <xacro:macro name="m_link_box_inertia" params="name origin_xyz origin_rpy m w d h">
    <link name="${name}">
      <inertial>
        <mass value="${m}"/>
        <origin rpy="${origin_rpy}" xyz="${origin_xyz}"/>
        <inertia ixx="${m*(d*d+h*h)/12}" ixy="0" ixz="0"
                 iyy="${m*(w*w+h*h)/12}" iyz="0"
                 izz="${m*(w*w+d*d)/12}"/>
      </inertial>
      <collision>
        <origin rpy="${origin_rpy}" xyz="${origin_xyz}"/>
        <geometry>
          <box size="${w} ${d} ${h}"/>
        </geometry>
      </collision>
      <visual>
        <origin rpy="${origin_rpy}" xyz="${origin_xyz}"/>
        <geometry>
          <box size="${w} ${d} ${h}"/>
        </geometry>
        <xacro:material_clay_brown/>
      </visual>
    </link>
  </xacro:macro>

  <!-- Mesh link Macro Box -->
  <xacro:macro name="m_link_mesh_box" params="name origin_xyz origin_rpy meshfile meshscale m w d h">
    <link name="${name}">
      <inertial>
        <mass value="${m}"/>
        <origin rpy="${origin_rpy}" xyz="${origin_xyz}"/>
        <inertia ixx="${m*(d*d+h*h)/12}" ixy="0" ixz="0"
                 iyy="${m*(w*w+h*h)/12}" iyz="0"
                 izz="${m*(w*w+d*d)/12}"/>
      </inertial>
      <collision>
        <origin rpy="${origin_rpy}" xyz="${origin_xyz}"/>
        <geometry>
            <mesh filename="${meshfile}" scale="${meshscale}"/>
        </geometry>
      </collision>
      <visual>
        <origin rpy="${origin_rpy}" xyz="${origin_xyz}"/>
        <geometry>
            <mesh filename="${meshfile}" scale="${meshscale}"/>
        </geometry>
      </visual>
    </link>
  </xacro:macro>

  <!-- Mesh link Macro Cylinder -->
  <xacro:macro name="m_link_mesh_cyl" params="name origin_xyz origin_rpy meshfile meshscale m r l">
    <link name="${name}">
      <inertial>
        <mass value="${m}"/>
        <origin rpy="${origin_rpy}" xyz="${origin_xyz}"/>
        <inertia ixx="${m*(3*r*l+r*l)/12}" ixy="0.0" ixz="0.0"
                 iyy="${m*(3*r*r+l*l)/12}" iyz="0.0"
                 izz="${m*l*l/2}"/>
      </inertial>
      <collision>
        <origin rpy="${origin_rpy}" xyz="${origin_xyz}"/>
        <geometry>
            <mesh filename="${meshfile}" scale="${meshscale}"/>
        </geometry>
      </collision>
      <visual>
        <origin rpy="${origin_rpy}" xyz="${origin_xyz}"/>
        <geometry>
            <mesh filename="${meshfile}" scale="${meshscale}"/>
        </geometry>
      </visual>
    </link>
  </xacro:macro>
</robot>
